Workbook

Sheet README
B2: blyp. authoritative product workbook
B3: One evidence-backed record for every defined feature, implementation path, verification state and production conclusion.
B6: Workbook anchor | C6: Reviewed source revision: 8bc0dcb2a1da1b21368c5536aaeef829d587f316. Generated: 2026-08-02T04:33:11+00:00. The repository had a pre-existing working-tree modification to backend/blyp-live-service/src/economy/infra.ts; source conclusions otherwise use the clean archived revision.
B7: What one row means | C7: Each Feature Register row is an independently traceable product requirement. Parent and record-type fields preserve hierarchy. Implementation, reachability, completeness, verification and production conclusion are separate facts.
B8: Implementation | C8: Describes what is physically present in the reviewed source: client screens, routes, services, stores, workers, external systems, configuration and deployable boundaries. `Not found` means no mapped implementation was found; `Unknown` means available evidence is insufficient.
B9: How it runs | C9: Use Runtime Path ID and Runtime Path Narrative in the Feature Register, then inspect the Runtime Paths sheet for the end-to-end actor, entrypoint, client, server, data, asynchronous work, external dependencies and failure behaviour.
B10: Finished | C10: Functional Completeness compares the mapped implementation with the stated requirement. It does not certify security, scale, legal approval, store acceptance or release operations.
B11: Production ready | C11: A feature may be marked Production ready only when every applicable production gate passes on the exact release candidate, no unresolved blocker remains, and Approved By plus Approved At are populated. This workbook currently contains zero production-ready approvals.
B12: Evidence | C12: Source, test and observed evidence identifiers link to the Evidence Ledger. Documentation and historical audits are leads only unless tied to exact revision, build or observed-runtime evidence.
B13: Editing | C13: Use the controlled dropdowns in the Feature Register. Do not replace Unknown with a positive status without evidence. Add new evidence to the Evidence Ledger first, preserve revision/build identifiers, and record material decisions in Decisions & Changes.
B14: Live streaming | C14: The feature is implemented and user-reachable. It remains blocked because later signed-device candidates retained a black host preview and the Firebase HLS and separate AWS IVS paths are not reconciled.
B15: Wallet and gifting | C15: The visible wallet and gift interface is implemented. It remains blocked because the current mobile Firestore economy and the hosted PostgreSQL economy are conflicting authorities, with no current executed transaction and reconciliation proof.

Sheet Executive Summary
A1: blyp. product source of truth
A2: 633 normalized feature records • evidence anchored to 8bc0dcb2a1da • generated 2026-08-02T04:33:11+00:00
A4: Defined records | D4: Product areas | G4: Implemented in some form | J4: Complete against requirement | M4: Physical-device observed | P4: Production ready
A5: =COUNTA('Feature Register'!$A$2:$A$634) | D5: =COUNTA($A$66:$A$95) | G5: =COUNTIF('Feature Register'!$S$2:$S$634,"Scaffold only")+COUNTIF('Feature Register'!$S$2:$S$634,"UI only")+COUNTIF('Feature Register'!$S$2:$S$634,"Backend only")+COUNTIF('Feature Register'!$S$2:$S$634,"Partial")+COUNTIF('Feature Register'!$S$2:$S$634,"End-to-end present")+COUNTIF('Feature Register'!$S$2:$S$634,"Conflicting implementations") | J5: =COUNTIF('Feature Register'!$AG$2:$AG$634,"Complete against stated requirement") | M5: =COUNTIF('Feature Register'!$AJ$2:$AJ$634,"Physical device observed") | P5: =COUNTIF('Feature Register'!$BE$2:$BE$634,"Production ready")
A7: No feature is automatically production-approved. `Production ready` requires every applicable gate, an exact release candidate, and accountable approval.
A9: Physical implementation
A10: Status | B10: Count | C10: % of 633
A11: End-to-end present | B11: =COUNTIF('Feature Register'!$S$2:$S$634,A11) | C11: =B11/$A$5
A12: Partial | B12: =COUNTIF('Feature Register'!$S$2:$S$634,A12) | C12: =B12/$A$5
A13: UI only | B13: =COUNTIF('Feature Register'!$S$2:$S$634,A13) | C13: =B13/$A$5
A14: Backend only | B14: =COUNTIF('Feature Register'!$S$2:$S$634,A14) | C14: =B14/$A$5
A15: Conflicting implementations | B15: =COUNTIF('Feature Register'!$S$2:$S$634,A15) | C15: =B15/$A$5
A16: Scaffold only | B16: =COUNTIF('Feature Register'!$S$2:$S$634,A16) | C16: =B16/$A$5
A17: Not found | B17: =COUNTIF('Feature Register'!$S$2:$S$634,A17) | C17: =B17/$A$5
A18: Unknown | B18: =COUNTIF('Feature Register'!$S$2:$S$634,A18) | C18: =B18/$A$5
A21: Functional completeness
A22: Status | B22: Count | C22: % of 633
A23: Complete against stated requirement | B23: =COUNTIF('Feature Register'!$AG$2:$AG$634,A23) | C23: =B23/$A$5
A24: Incomplete | B24: =COUNTIF('Feature Register'!$AG$2:$AG$634,A24) | C24: =B24/$A$5
A25: Not started | B25: =COUNTIF('Feature Register'!$AG$2:$AG$634,A25) | C25: =B25/$A$5
A26: Not assessable | B26: =COUNTIF('Feature Register'!$AG$2:$AG$634,A26) | C26: =B26/$A$5
A27: Unknown | B27: =COUNTIF('Feature Register'!$AG$2:$AG$634,A27) | C27: =B27/$A$5
A30: Verification
A31: Status | B31: Count | C31: % of 633
A32: Physical device observed | B32: =COUNTIF('Feature Register'!$AJ$2:$AJ$634,A32) | C32: =B32/$A$5
A33: Conflicting evidence | B33: =COUNTIF('Feature Register'!$AJ$2:$AJ$634,A33) | C33: =B33/$A$5
A34: Source traced | B34: =COUNTIF('Feature Register'!$AJ$2:$AJ$634,A34) | C34: =B34/$A$5
A35: Build verified | B35: =COUNTIF('Feature Register'!$AJ$2:$AJ$634,A35) | C35: =B35/$A$5
A36: Automated test passed | B36: =COUNTIF('Feature Register'!$AJ$2:$AJ$634,A36) | C36: =B36/$A$5
A37: Not verified | B37: =COUNTIF('Feature Register'!$AJ$2:$AJ$634,A37) | C37: =B37/$A$5
A38: Unknown | B38: =COUNTIF('Feature Register'!$AJ$2:$AJ$634,A38) | C38: =B38/$A$5
A41: Production conclusion
A42: Status | B42: Count | C42: % of 633
A43: Production ready | B43: =COUNTIF('Feature Register'!$BE$2:$BE$634,A43) | C43: =B43/$A$5
A44: Ready for production validation | B44: =COUNTIF('Feature Register'!$BE$2:$BE$634,A44) | C44: =B44/$A$5
A45: Blocked | B45: =COUNTIF('Feature Register'!$BE$2:$BE$634,A45) | C45: =B45/$A$5
A46: Development required | B46: =COUNTIF('Feature Register'!$BE$2:$BE$634,A46) | C46: =B46/$A$5
A47: Not assessed | B47: =COUNTIF('Feature Register'!$BE$2:$BE$634,A47) | C47: =B47/$A$5
A48: Unknown | B48: =COUNTIF('Feature Register'!$BE$2:$BE$634,A48) | C48: =B48/$A$5
A49: Not applicable | B49: =COUNTIF('Feature Register'!$BE$2:$BE$634,A49) | C49: =B49/$A$5
...

Sheet Feature Register
A1: Feature ID | B1: Parent Feature ID | C1: Product Area | D1: Area Number | E1: Area Sequence | F1: Record Type | G1: Feature Name | H1: Source Requirement | I1: Source Location | J1: Normalization Location | K1: Intended Scope | L1: Intended Actor | M1: Intended Surface | N1: Intended Outcome | O1: Acceptance Criteria | P1: Dependencies | Q1: Prior Audit Label | R1: Prior Audit Note | S1: Implementation State | T1: Client Entry and Navigation | U1: UI Components and Screens | V1: Client State and Services | W1: Server Routes and Handlers | X1: Data Stores | Y1: Workers and Async Paths | Z1: External Services | AA1: Configuration and Permissions | AB1: Deployable Runtime | AC1: Runtime Path ID | AD1: Runtime Path Narrative | AE1: Reachability | AF1: Reachability Detail | AG1: Functional Completeness | AH1: Complete Against Requirement? | AI1: Known Gaps | AJ1: Verification State | AK1: Source Evidence IDs | AL1: Test Evidence IDs | AM1: Observed Evidence IDs | AN1: Last Verified At | AO1: Verified Revision or Build | AP1: Evidence Confidence | AQ1: Gate — Scope and Acceptance | AR1: Gate — Architecture and Authority | AS1: Gate — Functional Behaviour | AT1: Gate — Identity and Permissions | AU1: Gate — Data Integrity | AV1: Gate — Privacy and Consent | AW1: Gate — Safety and Abuse | AX1: Gate — Commerce and Entitlement | AY1: Gate — Security | AZ1: Gate — Reliability and Scale | BA1: Gate — Observability and Operations | BB1: Gate — Accessibility and Device Coverage | BC1: Gate — Legal and Policy | BD1: Gate — Release-candidate Verification | BE1: Production Conclusion | BF1: Production Blockers | BG1: Required Next Evidence | BH1: Owner | BI1: Approved By | BJ1: Approved At | BK1: Review Notes | BL1: Last Updated
A2: BLYP-01-001 | C2: BLYP Bar and AI-assisted posting | D2: 1 | E2: 1 | F2: Feature | G2: BLYP Bar conversational interface | H2: BLYP Bar conversational interface | I2: /home/ubuntu/blyp_product_requirements.md :: Section 1 — BLYP Bar and AI-assisted posting | J2: /home/ubuntu/BLYP_COMPLETE_FEATURE_LIST.md:16 | K2: Required | L2: Applicable BLYP member | M2: BLYP mobile application and supporting production services | N2: BLYP Bar conversational interface | O2: Not explicitly defined in the product source; requires accountable product approval before production sign-off. | Q2: Yes | R2: a bounded BLYP Bar dispatcher exists. | S2: Not found | T2: Not found | U2: Not found | V2: Not found | W2: Not found | X2: Unknown | Y2: Not found | Z2: Not found | AA2: Not found | AB2: Unknown | AE2: Unknown | AG2: Not started | AH2: No | AI2: Searched all non-node_modules source files for 'BLYP Bar', 'BlypBar', 'blypBar', 'blyp-bar', 'blyp_bar'. No component, screen, service, route, or data model matching a BLYP Bar conversational interface was found. The feature may exist under a different identifier not covered by this search. | AJ2: Not verified | AK2: EV-01-0001 | AO2: 8bc0dcb2a1da1b21368c5536aaeef829d587f316 | AP2: Low | AQ2: Not assessed | AR2: Not assessed | AS2: Fail | AT2: Not assessed | AU2: Not assessed | AV2: Not assessed | AW2: Not assessed | AX2: Not assessed | AY2: Not assessed | AZ2: Not assessed | BA2: Not assessed | BB2: Not assessed | BC2: Not assessed | BD2: Not assessed | BE2: Development required | BF2: Physical implementation is not complete against the stated requirement.; Searched all non-node_modules source files for 'BLYP Bar', 'BlypBar', 'blypBar', 'blyp-bar', 'blyp_bar'. No component, screen, service, route, or data model matching a BLYP Bar conversational interface was found. The feature may exist under a different identifier not covered by this search. | BG2: Identify the actual file/component name for the BLYP Bar dispatcher; search for it; confirm wiring in navigation stack. | BK2: Evidence reconciled against the reviewed source revision. No production approval is inferred from implementation or file presence. | BL2: 2026-08-02
A3: BLYP-01-002 | C3: BLYP Bar and AI-assisted posting | D3: 1 | E3: 2 | F3: Feature | G3: Battle-request interpretation | H3: Battle-request interpretation | I3: /home/ubuntu/blyp_product_requirements.md :: Section 1 — BLYP Bar and AI-assisted posting | J3: /home/ubuntu/BLYP_COMPLETE_FEATURE_LIST.md:17 | K3: Required | L3: Applicable BLYP member | M3: BLYP mobile application and supporting production services | N3: Battle-request interpretation | O3: Not explicitly defined in the product source; requires accountable product approval before production sign-off. | Q3: Yes | S3: Not found | T3: Not found | U3: Not found | V3: Not found | W3: Not found | X3: Unknown | Y3: Not found | Z3: Not found | AA3: Not found | AB3: Unknown | AE3: Unknown | AG3: Not started | AH3: No | AI3: No client-side battle-request parsing or interpretation layer found. Backend economy route POST /promote/battle exists but is a coin-spend feature unrelated to BLYP Bar dispatch. Searched for 'battle' in client AI/dispatch context. | AJ3: Not verified | AK3: EV-01-0002;EV-01-0003 | AO3: 8bc0dcb2a1da1b21368c5536aaeef829d587f316 | AP3: Low | AQ3: Not assessed | AR3: Not assessed | AS3: Fail | AT3: Not assessed | AU3: Not assessed | AV3: Not assessed | AW3: Not assessed | AX3: Not assessed | AY3: Not assessed | AZ3: Not assessed | BA3: Not assessed | BB3: Not assessed | BC3: Not assessed | BD3: Not assessed | BE3: Development required | BF3: Physical implementation is not complete against the stated requirement.; No client-side battle-request parsing or interpretation layer found. Backend economy route POST /promote/battle exists but is a coin-spend feature unrelated to BLYP Bar dispatch. Searched for 'battle' in client AI/dispatch context. | BG3: Identify BLYP Bar dispatcher code; search for battle-request parsing logic within it. | BK3: Evidence reconciled against the reviewed source revision. No production approval is inferred from implementation or file presence. | BL3: 2026-08-02
A4: BLYP-01-003 | C4: BLYP Bar and AI-assisted posting | D4: 1 | E4: 3 | F4: Feature | G4: Opponent resolution for a Battle request | H4: Opponent resolution for a Battle request | I4: /home/ubuntu/blyp_product_requirements.md :: Section 1 — BLYP Bar and AI-assisted posting | J4: /home/ubuntu/BLYP_COMPLETE_FEATURE_LIST.md:18 | K4: Required | L4: Applicable BLYP member | M4: BLYP mobile application and supporting production services | N4: Opponent resolution for a Battle request | O4: Not explicitly defined in the product source; requires accountable product approval before production sign-off. | Q4: Yes | S4: Not found | T4: Not found | U4: Not found | V4: Not found | W4: Not found | X4: Unknown | Y4: Not found | Z4: Not found | AA4: Not found | AB4: Unknown | AE4: Unknown | AG4: Not started | AH4: No | AI4: No opponent resolution logic found in client source. Searched for 'opponent', 'resolution', 'battle' in client AI/dispatch context. No user lookup or matching service for battle opponents found. | AJ4: Not verified | AK4: EV-01-0002;EV-01-0003 | AO4: 8bc0dcb2a1da1b21368c5536aaeef829d587f316 | AP4: Low | AQ4: Not assessed | AR4: Not assessed | AS4: Fail | AT4: Not assessed | AU4: Not assessed | AV4: Not assessed | AW4: Not assessed | AX4: Not assessed | AY4: Not assessed | AZ4: Not assessed | BA4: Not assessed | BB4: Not assessed | BC4: Not assessed | BD4: Not assessed | BE4: Development required | BF4: Physical implementation is not complete against the stated requirement.; No opponent resolution logic found in client source. Searched for 'opponent', 'resolution', 'battle' in client AI/dispatch context. No user lookup or matching service for battle opponents found. | BG4: Identify BLYP Bar dispatcher; search for opponent resolution/lookup logic. | BK4: Evidence reconciled against the reviewed source revision. No production approval is inferred from implementation or file presence. | BL4: 2026-08-02
A5: BLYP-01-004 | C5: BLYP Bar and AI-assisted posting | D5: 1 | E5: 4 | F5: Feature | G5: Prefilled Battle creation flow | H5: Prefilled Battle creation flow | I5: /home/ubuntu/blyp_product_requirements.md :: Section 1 — BLYP Bar and AI-assisted posting | J5: /home/ubuntu/BLYP_COMPLETE_FEATURE_LIST.md:19 | K5: Required | L5: Applicable BLYP member | M5: BLYP mobile application and supporting production services | N5: Prefilled Battle creation flow | O5: Not explicitly defined in the product source; requires accountable product approval before production sign-off. | Q5: Yes | S5: Not found | T5: Not found | U5: Not found | V5: Not found | W5: Not found | X5: Unknown | Y5: Not found | Z5: Not found | AA5: Not found | AB5: Unknown | AE5: Unknown | AG5: Not started | AH5: No | AI5: No prefilled battle creation flow found. Searched for 'prefill', 'Prefill', 'battle' in client navigation/creation context. No navigation to a battle creation screen with pre-populated fields was found. | AJ5: Not verified | AK5: EV-01-0002;EV-01-0003 | AO5: 8bc0dcb2a1da1b21368c5536aaeef829d587f316 | AP5: Low | AQ5: Not assessed | AR5: Not assessed | AS5: Fail | AT5: Not assessed | AU5: Not assessed | AV5: Not assessed | AW5: Not assessed | AX5: Not assessed | AY5: Not assessed | AZ5: Not assessed | BA5: Not assessed | BB5: Not assessed | BC5: Not assessed | BD5: Not assessed | BE5: Development required | BF5: Physical implementation is not complete against the stated requirement.; No prefilled battle creation flow found. Searched for 'prefill', 'Prefill', 'battle' in client navigation/creation context. No navigation to a battle creation screen with pre-populated fields was found. | BG5: Identify BLYP Bar dispatcher; search for prefilled battle creation navigation. | BK5: Evidence reconciled against the reviewed source revision. No production approval is inferred from implementation or file presence. | BL5: 2026-08-02
A6: BLYP-01-005 | C6: BLYP Bar and AI-assisted posting | D6: 1 | E6: 5 | F6: Feature | G6: Event watches | H6: Event watches | I6: /home/ubuntu/blyp_product_requirements.md :: Section 1 — BLYP Bar and AI-assisted posting | J6: /home/ubuntu/BLYP_COMPLETE_FEATURE_LIST.md:20 | K6: Required | L6: Authenticated or eligible viewer | M6: BLYP mobile application and supporting production services | N6: Event watches | O6: Not explicitly defined in the product source; requires accountable product approval before production sign-off. | Q6: Yes | S6: Not found | T6: Not found | U6: Not found | V6: Not found | W6: Not found | X6: Unknown | Y6: Not found | Z6: Not found | AA6: Not found | AB6: Unknown | AE6: Unknown | AG6: Not started | AH6: No | AI6: No event-watch subscription feature found. Searched for 'watch', 'Watch' in event/creator context. Only found totalWatchTime analytics and 'watching' viewer count labels. No event watch data model, service, or UI found. | AJ6: Not verified | AK6: EV-01-0004 | AO6: 8bc0dcb2a1da1b21368c5536aaeef829d587f316 | AP6: Low | AQ6: Not assessed | AR6: Not assessed | AS6: Fail | AT6: Not assessed | AU6: Not assessed | AV6: Not assessed | AW6: Not assessed | AX6: Not assessed | AY6: Not assessed | AZ6: Not assessed | BA6: Not assessed | BB6: Not assessed | BC6: Not assessed | BD6: Not assessed | BE6: Development required | BF6: Physical implementation is not complete against the stated requirement.; No event-watch subscription feature found. Searched for 'watch', 'Watch' in event/creator context. Only found totalWatchTime analytics and 'watching' viewer count labels. No event watch data model, service, or UI found. | BG6: Search for event subscription/watch feature under alternate identifiers; check Firestore collections for watch/subscription documents. | BK6: Evidence reconciled against the reviewed source revision. No production approval is inferred from implementation or file presence. | BL6: 2026-08-02
A7: BLYP-01-006 | C7: BLYP Bar and AI-assisted posting | D7: 1 | E7: 6 | F7: Feature | G7: Creator/user watches | H7: Creator/user watches | I7: /home/ubuntu/blyp_product_requirements.md :: Section 1 — BLYP Bar and AI-assisted posting | J7: /home/ubuntu/BLYP_COMPLETE_FEATURE_LIST.md:21 | K7: Required | L7: Authenticated creator or host | M7: BLYP mobile application and supporting production services | N7: Creator/user watches | O7: Not explicitly defined in the product source; requires accountable product approval before production sign-off. | Q7: Yes | S7: Not found | T7: Not found | U7: Not found | V7: Not found | W7: Not found | X7: Unknown | Y7: Not found | Z7: Not found | AA7: Not found | AB7: Unknown | AE7: Unknown | AG7: Not started | AH7: No | AI7: No creator/user watch subscription feature found. Searched for 'watch', 'Watch', 'creator', 'follow', 'subscribe' in relevant context. No creator-watch data model, service, or UI found. | AJ7: Not verified | AK7: EV-01-0004 | AO7: 8bc0dcb2a1da1b21368c5536aaeef829d587f316 | AP7: Low | AQ7: Not assessed | AR7: Not assessed | AS7: Fail | AT7: Not assessed | AU7: Not assessed | AV7: Not assessed | AW7: Not assessed | AX7: Not assessed | AY7: Not assessed | AZ7: Not assessed | BA7: Not assessed | BB7: Not assessed | BC7: Not assessed | BD7: Not assessed | BE7: Development required | BF7: Physical implementation is not complete against the stated requirement.; No creator/user watch subscription feature found. Searched for 'watch', 'Watch', 'creator', 'follow', 'subscribe' in relevant context. No creator-watch data model, service, or UI found. | BG7: Search for creator/user subscription feature under alternate identifiers; check Firestore collections. | BK7: Evidence reconciled against the reviewed source revision. No production approval is inferred from implementation or file presence. | BL7: 2026-08-02
A8: BLYP-01-007 | C8: BLYP Bar and AI-assisted posting | D8: 1 | E8: 7 | F8: Feature | G8: Notification when a watched creator next goes live | H8: Notification when a watched creator next goes live | I8: /home/ubuntu/blyp_product_requirements.md :: Section 1 — BLYP Bar and AI-assisted posting | J8: /home/ubuntu/BLYP_COMPLETE_FEATURE_LIST.md:22 | K8: Required | L8: Authenticated creator or host | M8: BLYP mobile application and supporting production services | N8: Notification when a watched creator next goes live | O8: Not explicitly defined in the product source; requires accountable product approval before production sign-off. | Q8: Partial | R8: watch persistence exists; the complete notification journey needs verification. | S8: Not found | T8: Not found | U8: Not found | V8: Not found | W8: Not found | X8: Unknown | Y8: Not found | Z8: Not found | AA8: Not found | AB8: Unknown | AE8: Unknown | AG8: Not started | AH8: No | AI8: No notification-when-watched-creator-goes-live feature found. Searched for 'reminder', 'Reminder', 'notification', 'Notification', 'live', 'watch' in relevant context. No push notification trigger for watched creator going live was found. | AJ8: Not verified | AK8: EV-01-0004;EV-01-0005 | AO8: 8bc0dcb2a1da1b21368c5536aaeef829d587f316 | AP8: Low | AQ8: Not assessed | AR8: Not assessed | AS8: Fail | AT8: Not assessed | AU8: Not assessed | AV8: Not assessed | AW8: Not assessed | AX8: Not assessed | AY8: Not assessed | AZ8: Not assessed | BA8: Not assessed | BB8: Not assessed | BC8: Not assessed | BD8: Not assessed | BE8: Development required | BF8: Physical implementation is not complete against the stated requirement.; No notification-when-watched-creator-goes-live feature found. Searched for 'reminder', 'Reminder', 'notification', 'Notification', 'live', 'watch' in relevant context. No push notification trigger for watched creator going live was found. | BG8: Search for push notification service and live-start trigger; check Firebase Functions for notification dispatch. | BK8: Evidence reconciled against the reviewed source revision. No production approval is inferred from implementation or file presence. | BL8: 2026-08-02
A9: BLYP-01-008 | C9: BLYP Bar and AI-assisted posting | D9: 1 | E9: 8 | F9: Feature | G9: Single-reminder creation | H9: Single-reminder creation | I9: /home/ubuntu/blyp_product_requirements.md :: Section 1 — BLYP Bar and AI-assisted posting | J9: /home/ubuntu/BLYP_COMPLETE_FEATURE_LIST.md:23 | K9: Required | L9: Applicable BLYP member | M9: BLYP mobile application and supporting production services | N9: Single-reminder creation | O9: Not explicitly defined in the product source; requires accountable product approval before production sign-off. | Q9: Yes | S9: Not found | T9: Not found | U9: Not found | V9: Not found | W9: Not found | X9: Unknown | Y9: Not found | Z9: Not found | AA9: Not found | AB9: Unknown | AE9: Unknown | AG9: Not started | AH9: No | AI9: No single-reminder creation feature found. Searched for 'reminder', 'Reminder' across all source files - zero results. | AJ9: Not verified | AK9: EV-01-0005 | AO9: 8bc0dcb2a1da1b21368c5536aaeef829d587f316 | AP9: Low | AQ9: Not assessed | AR9: Not assessed | AS9: Fail | AT9: Not assessed | AU9: Not assessed | AV9: Not assessed | AW9: Not assessed | AX9: Not assessed | AY9: Not assessed | AZ9: Not assessed | BA9: Not assessed | BB9: Not assessed | BC9: Not assessed | BD9: Not assessed | BE9: Development required | BF9: Physical implementation is not complete against the stated requirement.; No single-reminder creation feature found. Searched for 'reminder', 'Reminder' across all source files - zero results. | BG9: Search for reminder/scheduling feature under alternate identifiers; check Firebase Functions for scheduled notifications. | BK9: Evidence reconciled against the reviewed source revision. No production approval is inferred from implementation or file presence. | BL9: 2026-08-02
A10: BLYP-01-009 | C10: BLYP Bar and AI-assisted posting | D10: 1 | E10: 9 | F10: Feature | G10: Multi-event reminder planning | H10: Multi-event reminder planning | I10: /home/ubuntu/blyp_product_requirements.md :: Section 1 — BLYP Bar and AI-assisted posting | J10: /home/ubuntu/BLYP_COMPLETE_FEATURE_LIST.md:24 | K10: Required | L10: Applicable BLYP member | M10: BLYP mobile application and supporting production services | N10: Multi-event reminder planning | O10: Not explicitly defined in the product source; requires accountable product approval before production sign-off. | Q10: Yes | S10: Not found | T10: Not found | U10: Not found | V10: Not found | W10: Not found | X10: Unknown | Y10: Not found | Z10: Not found | AA10: Not found | AB10: Unknown | AE10: Unknown | AG10: Not started | AH10: No | AI10: No multi-event reminder planning feature found. Searched for 'reminder', 'Reminder', 'multi', 'planning' across all source files - zero results for reminder. | AJ10: Not verified | AK10: EV-01-0005 | AO10: 8bc0dcb2a1da1b21368c5536aaeef829d587f316 | AP10: Low | AQ10: Not assessed | AR10: Not assessed | AS10: Fail | AT10: Not assessed | AU10: Not assessed | AV10: Not assessed | AW10: Not assessed | AX10: Not assessed | AY10: Not assessed | AZ10: Not assessed | BA10: Not assessed | BB10: Not assessed | BC10: Not assessed | BD10: Not assessed | BE10: Development required | BF10: Physical implementation is not complete against the stated requirement.; No multi-event reminder planning feature found. Searched for 'reminder', 'Reminder', 'multi', 'planning' across all source files - zero results for reminder. | BG10: Search for multi-event scheduling/reminder feature under alternate identifiers. | BK10: Evidence reconciled against the reviewed source revision. No production approval is inferred from implementation or file presence. | BL10: 2026-08-02
A11: BLYP-01-010 | C11: BLYP Bar and AI-assisted posting | D11: 1 | E11: 10 | F11: Feature | G11: In-app content search from the BLYP Bar | H11: In-app content search from the BLYP Bar | I11: /home/ubuntu/blyp_product_requirements.md :: Section 1 — BLYP Bar and AI-assisted posting | J11: /home/ubuntu/BLYP_COMPLETE_FEATURE_LIST.md:25 | K11: Required | L11: Applicable BLYP member | M11: BLYP mobile application and supporting production services | N11: In-app content search from the BLYP Bar | O11: Not explicitly defined in the product source; requires accountable product approval before production sign-off. | P11: Firestore (imported but mock data used); Firestore (imported but mock data used for posts); hardcoded suggestedUsers; Firebase config (src/config/firebase.js) | Q11: Yes | S11: Partial | T11: App.js Stack.Screen name='Search' (line 199); SearchScreen.js | U11: SearchScreen.js; SearchResultsScreen.js | V11: searchService.globalSearch / searchUsers / searchPosts / searchHashtags / searchLocations | W11: Not found (client-side only; Firestore queries not fully wired) | X11: Firestore (imported but mock data used for posts); hardcoded suggestedUsers | Y11: Not found | Z11: Firestore (imported but mock data used) | AA11: Firebase config (src/config/firebase.js) | AB11: Expo mobile client | AC11: RP-002 | AD11: User navigates to Search tab; SearchScreen calls searchService.globalSearch; searchService returns mock posts and filtered hardcoded users; no BLYP Bar integration found. | AE11: User reachable | AF11: App.js Stack.Screen name='Search' (line 199); SearchScreen.js; User navigates to Search tab; SearchScreen calls searchService.globalSearch; searchService returns mock posts and filtered hardcoded users; no BLYP Bar integration found. | AG11: Incomplete | AH11: No | AI11: searchPosts returns mock data (searchService.js:101-102). No BLYP Bar integration found. Search is not AI-powered. Firestore-backed live search not confirmed. No BLYP Bar entry point found. | AJ11: Source traced | AK11: EV-01-0006;EV-01-0007;EV-01-0037 | AO11: 8bc0dcb2a1da1b21368c5536aaeef829d587f316 | AP11: Medium | AQ11: Not assessed | AR11: Not assessed | AS11: Fail | AT11: Not assessed | AU11: Not assessed | AV11: Not assessed | AW11: Not assessed | AX11: Not assessed | AY11: Not assessed | AZ11: Not assessed | BA11: Not assessed | BB11: Not assessed | BC11: Not assessed | BD11: Not assessed | BE11: Development required | BF11: Physical implementation is not complete against the stated requirement.; searchPosts returns mock data (searchService.js:101-102). No BLYP Bar integration found. Search is not AI-powered. Firestore-backed live search not confirmed. No BLYP Bar entry point found. | BG11: Confirm live Firestore search queries; confirm BLYP Bar integration if required; test on device. | BK11: Evidence reconciled against the reviewed source revision. No production approval is inferred from implementation or file presence. | BL11: 2026-08-02
A12: BLYP-01-011 | C12: BLYP Bar and AI-assisted posting | D12: 1 | E12: 11 | F12: Feature | G12: Plus-gated Gemini answers | H12: Plus-gated Gemini answers | I12: /home/ubuntu/blyp_product_requirements.md :: Section 1 — BLYP Bar and AI-assisted posting | J12: /home/ubuntu/BLYP_COMPLETE_FEATURE_LIST.md:26 | K12: Required | L12: Applicable BLYP member | M12: BLYP mobile application and supporting production services | N12: Plus-gated Gemini answers | O12: Not explicitly defined in the product source; requires accountable product approval before production sign-off. | Q12: Yes | S12: Not found | T12: Not found | U12: Not found | V12: Not found | W12: Not found | X12: Unknown | Y12: Not found | Z12: Not found | AA12: Not found | AB12: Unknown | AE12: Unknown | AG12: Not started | AH12: No | AI12: No Plus-gated Gemini answers feature found. Searched for 'plus', 'Plus', 'premium', 'subscription', 'entitlement', 'gated' across all source files - zero results. No subscription tier or entitlement check for Gemini was found. | AJ12: Not verified | AK12: EV-01-0008 | AO12: 8bc0dcb2a1da1b21368c5536aaeef829d587f316 | AP12: Low | AQ12: Not assessed | AR12: Not assessed | AS12: Fail | AT12: Not assessed | AU12: Not assessed | AV12: Not assessed | AW12: Not assessed | AX12: Not assessed | AY12: Not assessed | AZ12: Not assessed | BA12: Not assessed | BB12: Not assessed | BC12: Not assessed | BD12: Not assessed | BE12: Development required | BF12: Physical implementation is not complete against the stated requirement.; No Plus-gated Gemini answers feature found. Searched for 'plus', 'Plus', 'premium', 'subscription', 'entitlement', 'gated' across all source files - zero results. No subscription tier or entitlement check for Gemini was found. | BG12: Search for subscription/entitlement service; check backend routes for Plus tier; check Firestore for user subscription documents. | BK12: Evidence reconciled against the reviewed source revision. No production approval is inferred from implementation or file presence. | BL12: 2026-08-02
A13: BLYP-01-012 | C13: BLYP Bar and AI-assisted posting | D13: 1 | E13: 12 | F13: Feature | G13: Generic autonomous action execution | H13: Generic autonomous action execution | I13: /home/ubuntu/blyp_product_requirements.md :: Section 1 — BLYP Bar and AI-assisted posting | J13: /home/ubuntu/BLYP_COMPLETE_FEATURE_LIST.md:27 | K13: Required | L13: Applicable BLYP member | M13: BLYP mobile application and supporting production services | N13: Generic autonomous action execution | O13: Not explicitly defined in the product source; requires accountable product approval before production sign-off. | Q13: No evidence | S13: Not found | T13: Not found | U13: Not found | V13: Not found | W13: Not found | X13: Unknown | Y13: Not found | Z13: Not found | AA13: Not found | AB13: Unknown | AE13: Unknown | AG13: Not started | AH13: No | AI13: No generic autonomous action execution framework found. Searched for 'autonomous', 'Autonomous', 'action execution', 'generic action' across all source files - zero results. | AJ13: Not verified | AK13: EV-01-0009 | AO13: 8bc0dcb2a1da1b21368c5536aaeef829d587f316 | AP13: Low | AQ13: Not assessed | AR13: Not assessed | AS13: Fail | AT13: Not assessed | AU13: Not assessed | AV13: Not assessed | AW13: Not assessed | AX13: Not assessed | AY13: Not assessed | AZ13: Not assessed | BA13: Not assessed | BB13: Not assessed | BC13: Not assessed | BD13: Not assessed | BE13: Development required | BF13: Physical implementation is not complete against the stated requirement.; No generic autonomous action execution framework found. Searched for 'autonomous', 'Autonomous', 'action execution', 'generic action' across all source files - zero results. | BG13: Identify BLYP Bar dispatcher; search for action-execution framework within it. | BK13: Evidence reconciled against the reviewed source revision. No production approval is inferred from implementation or file presence. | BL13: 2026-08-02
A14: BLYP-01-013 | C14: BLYP Bar and AI-assisted posting | D14: 1 | E14: 13 | F14: Feature | G14: AI assistant integrated into the post composer | H14: AI assistant integrated into the post composer | I14: /home/ubuntu/blyp_product_requirements.md :: Section 1 — BLYP Bar and AI-assisted posting | J14: /home/ubuntu/BLYP_COMPLETE_FEATURE_LIST.md:28 | K14: Required | L14: Applicable BLYP member | M14: BLYP mobile application and supporting production services | N14: AI assistant integrated into the post composer | O14: Not explicitly defined in the product source; requires accountable product approval before production sign-off. | P14: Gemini API (generativelanguage.googleapis.com) via client-side key; Firestore posts collection (post creation); Firebase Storage (media upload); EXPO_PUBLIC_GEMINI_API_KEY (app.config.js:8-19); camera/microphone permissions (app.config.js:44-62) | Q14: Yes | S14: Partial | T14: App.js Stack.Screen name='Review' (line 214); CameraScreen navigates to Review; VoiceMemoScreen navigates to Review | U14: ReviewScreen.js | V14: aiService; speechToTextService; geminiSpeechService; mediaDescriptionService; isGeneratingContent; aiSuggestions; aiCaption state | W14: Not found (direct client-to-Gemini API calls) | X14: Firestore posts collection (post creation); Firebase Storage (media upload) | Y14: Not found | Z14: Gemini API (generativelanguage.googleapis.com) via client-side key | AA14: EXPO_PUBLIC_GEMINI_API_KEY (app.config.js:8-19); camera/microphone permissions (app.config.js:44-62) | AB14: Expo mobile client | AC14: RP-002 | AD14: User navigates to Camera/VoiceMemo, captures media, lands on ReviewScreen. ReviewScreen provides AI-assisted caption generation via Gemini API. No separate composer screen found; ReviewScreen IS the composer. | AE14: User reachable | AF14: App.js Stack.Screen name='Review' (line 214); CameraScreen navigates to Review; VoiceMemoScreen navigates to Review; User navigates to Camera/VoiceMemo, captures media, lands on ReviewScreen. ReviewScreen provides AI-assisted caption generation via Gemini API. No separate composer screen found; ReviewScreen IS the composer. | AG14: Incomplete | AH14: No | AI14: No dedicated 'composer' screen separate from ReviewScreen. AI calls go directly to Gemini API from client (not server-proxied). No BLYP Bar integration found. No Plus/entitlement gating. Three distinct caption choices not implemented. | AJ14: Source traced | AK14: EV-01-0010;EV-01-0033 | AO14: 8bc0dcb2a1da1b21368c5536aaeef829d587f316 | AP14: Medium | AQ14: Not assessed | AR14: Not assessed | AS14: Fail | AT14: Not assessed | AU14: Not assessed | AV14: Not assessed | AW14: Not assessed | AX14: Not assessed | AY14: Not assessed | AZ14: Not assessed | BA14: Not assessed | BB14: Not assessed | BC14: Not assessed | BD14: Not assessed | BE14: Development required | BF14: Physical implementation is not complete against the stated requirement.; No dedicated 'composer' screen separate from ReviewScreen. AI calls go directly to Gemini API from client (not server-proxied). No BLYP Bar integration found. No Plus/entitlement gating. Three distinct caption choices not implemented. | BG14: Confirm Gemini API key availability in production build; test AI generation on device; confirm BLYP Bar integration if required. | BK14: Evidence reconciled against the reviewed source revision. No production approval is inferred from implementation or file presence. | BL14: 2026-08-02
A15: BLYP-01-014 | C15: BLYP Bar and AI-assisted posting | D15: 1 | E15: 14 | F15: Feature | G15: Photo capture | H15: Photo capture | I15: /home/ubuntu/blyp_product_requirements.md :: Section 1 — BLYP Bar and AI-assisted posting | J15: /home/ubuntu/BLYP_COMPLETE_FEATURE_LIST.md:29 | K15: Required | L15: Applicable BLYP member | M15: BLYP mobile application and supporting production services | N15: Photo capture | O15: Not explicitly defined in the product source; requires accountable product approval before production sign-off. | P15: Device media library (save); Firebase Storage (upload via ReviewScreen); NSCameraUsageDescription; android.permission.CAMERA (app.config.js:44, 56) | Q15: Yes | S15: Partial | T15: App.js Stack.Screen name='Camera' (line 209); CameraScreen.js | U15: CameraScreen.js; CameraView (expo-camera) | V15: capturedPhotos; CameraView.takePictureAsync; MediaLibrary.saveToLibraryAsync | W15: Not found | X15: Device media library (save); Firebase Storage (upload via ReviewScreen) | Y15: Not found | Z15: Not found | AA15: NSCameraUsageDescription; android.permission.CAMERA (app.config.js:44, 56) | AB15: Expo mobile client | AC15: RP-002 | AD15: User opens Camera screen, takes photo, photo is added to capturedPhotos array, navigates to Review screen with photos. | AE15: User reachable | AF15: App.js Stack.Screen name='Camera' (line 209); CameraScreen.js; User opens Camera screen, takes photo, photo is added to capturedPhotos array, navigates to Review screen with photos. | AG15: Incomplete | AH15: No | AI15: Physical device camera not verified. Emulator detection present (CameraScreen.js:45-55). Production build not verified. | AJ15: Source traced | AK15: EV-01-0011;EV-01-0034;EV-01-0039 | AO15: 8bc0dcb2a1da1b21368c5536aaeef829d587f316 | AP15: Medium | AQ15: Not assessed | AR15: Not assessed | AS15: Fail | AT15: Not assessed | AU15: Not assessed | AV15: Not assessed | AW15: Not assessed | AX15: Not assessed | AY15: Not assessed | AZ15: Not assessed | BA15: Not assessed | BB15: Not assessed | BC15: Not assessed | BD15: Not assessed | BE15: Development required | BF15: Physical implementation is not complete against the stated requirement.; Physical device camera not verified. Emulator detection present (CameraScreen.js:45-55). Production build not verified. | BG15: Test photo capture on physical device; verify production build. | BK15: Evidence reconciled against the reviewed source revision. No production approval is inferred from implementation or file presence. | BL15: 2026-08-02
A16: BLYP-01-015 | C16: BLYP Bar and AI-assisted posting | D16: 1 | E16: 15 | F16: Feature | G16: Video recording | H16: Video recording | I16: /home/ubuntu/blyp_product_requirements.md :: Section 1 — BLYP Bar and AI-assisted posting | J16: /home/ubuntu/BLYP_COMPLETE_FEATURE_LIST.md:30 | K16: Required | L16: Applicable BLYP member | M16: BLYP mobile application and supporting production services | N16: Video recording | O16: Not explicitly defined in the product source; requires accountable product approval before production sign-off. | P16: Device media library (save); Firebase Storage (upload via ReviewScreen); NSMicrophoneUsageDescription; android.permission.RECORD_AUDIO; android.permission.CAMERA (app.config.js:45, 57-58) | Q16: Yes | S16: Partial | T16: App.js Stack.Screen name='Camera' (line 209); CameraScreen.js | U16: CameraScreen.js; CameraView (expo-camera) | V16: isRecording; CameraView.recordAsync; ImagePicker.launchImageLibraryAsync (video) | W16: Not found | X16: Device media library (save); Firebase Storage (upload via ReviewScreen) | Y16: Not found | Z16: Not found | AA16: NSMicrophoneUsageDescription; android.permission.RECORD_AUDIO; android.permission.CAMERA (app.config.js:45, 57-58) | AB16: Expo mobile client | AC16: RP-002 | AD16: User opens Camera screen, records video via CameraView.recordAsync or system video picker, navigates to Review screen with video. | AE16: User reachable | AF16: App.js Stack.Screen name='Camera' (line 209); CameraScreen.js; User opens Camera screen, records video via CameraView.recordAsync or system video picker, navigates to Review screen with video. | AG16: Incomplete | AH16: No | AI16: Video recording noted as unreliable on emulator (CameraScreen.js:51). Physical device not verified. Production build not verified. | AJ16: Source traced | AK16: EV-01-0012;EV-01-0034;EV-01-0039 | AO16: 8bc0dcb2a1da1b21368c5536aaeef829d587f316 | AP16: Medium | AQ16: Not assessed | AR16: Not assessed | AS16: Fail | AT16: Not assessed | AU16: Not assessed | AV16: Not assessed | AW16: Not assessed | AX16: Not assessed | AY16: Not assessed | AZ16: Not assessed | BA16: Not assessed | BB16: Not assessed | BC16: Not assessed | BD16: Not assessed | BE16: Development required | BF16: Physical implementation is not complete against the stated requirement.; Video recording noted as unreliable on emulator (CameraScreen.js:51). Physical device not verified. Production build not verified. | BG16: Test video recording on physical device; verify production build. | BK16: Evidence reconciled against the reviewed source revision. No production approval is inferred from implementation or file presence. | BL16: 2026-08-02
A17: BLYP-01-016 | C17: BLYP Bar and AI-assisted posting | D17: 1 | E17: 16 | F17: Feature | G17: Phone-gallery media selection | H17: Phone-gallery media selection | I17: /home/ubuntu/blyp_product_requirements.md :: Section 1 — BLYP Bar and AI-assisted posting | J17: /home/ubuntu/BLYP_COMPLETE_FEATURE_LIST.md:31 | K17: Required | L17: Applicable BLYP member | M17: BLYP mobile application and supporting production services | N17: Phone-gallery media selection | O17: Not explicitly defined in the product source; requires accountable product approval before production sign-off. | P17: Device photo library; Firebase Storage (upload via ReviewScreen); NSPhotoLibraryUsageDescription; expo-media-library plugin (app.config.js:46, 79) | Q17: Yes | S17: Partial | T17: App.js Stack.Screen name='Camera' (line 209); CameraScreen.js openGallery() | U17: CameraScreen.js; galleryButton (line 581-585); ImagePicker | V17: ImagePicker.launchImageLibraryAsync; allowsMultipleSelection:true; selectionLimit:10 | W17: Not found | X17: Device photo library; Firebase Storage (upload via ReviewScreen) | Y17: Not found | Z17: Not found | AA17: NSPhotoLibraryUsageDescription; expo-media-library plugin (app.config.js:46, 79) | AB17: Expo mobile client | AC17: RP-002 | AD17: User taps gallery button in CameraScreen, ImagePicker opens phone gallery, selected photos navigate to ReviewScreen with source='gallery'. | AE17: User reachable | AF17: App.js Stack.Screen name='Camera' (line 209); CameraScreen.js openGallery(); User taps gallery button in CameraScreen, ImagePicker opens phone gallery, selected photos navigate to ReviewScreen with source='gallery'. | AG17: Incomplete | AH17: No | AI17: Physical device gallery access not verified. Production build not verified. | AJ17: Source traced | AK17: EV-01-0013;EV-01-0034;EV-01-0039 | AO17: 8bc0dcb2a1da1b21368c5536aaeef829d587f316 | AP17: Medium | AQ17: Not assessed | AR17: Not assessed | AS17: Fail | AT17: Not assessed | AU17: Not assessed | AV17: Not assessed | AW17: Not assessed | AX17: Not assessed | AY17: Not assessed | AZ17: Not assessed | BA17: Not assessed | BB17: Not assessed | BC17: Not assessed | BD17: Not assessed | BE17: Development required | BF17: Physical implementation is not complete against the stated requirement.; Physical device gallery access not verified. Production build not verified. | BG17: Test gallery selection on physical device; verify production build. | BK17: Evidence reconciled against the reviewed source revision. No production approval is inferred from implementation or file presence. | BL17: 2026-08-02
A18: BLYP-01-017 | C18: BLYP Bar and AI-assisted posting | D18: 1 | E18: 17 | F18: Feature | G18: Audio/voice-memo capture | H18: Audio/voice-memo capture | I18: /home/ubuntu/blyp_product_requirements.md :: Section 1 — BLYP Bar and AI-assisted posting | J18: /home/ubuntu/BLYP_COMPLETE_FEATURE_LIST.md:32 | K18: Required | L18: Applicable BLYP member | M18: BLYP mobile application and supporting production services | N18: Audio/voice-memo capture | O18: Not explicitly defined in the product source; requires accountable product approval before production sign-off. | P18: Local file system (audio URI); Firebase Storage (upload via ReviewScreen); NSMicrophoneUsageDescription; expo-av plugin; android.permission.RECORD_AUDIO (app.config.js:45, 75, 89) | Q18: Yes | S18: Partial | T18: App.js Stack.Screen name='VoiceMemo' (line 222); VoiceMemoScreen.js; ReviewScreen.js (Audio import) | U18: VoiceMemoScreen.js; ReviewScreen.js (voice recording UI) | V18: Audio.Recording.createAsync (expo-av); speechToTextService.startRecording; voiceMemo state | W18: Not found | X18: Local file system (audio URI); Firebase Storage (upload via ReviewScreen) | Y18: Not found | Z18: Not found | AA18: NSMicrophoneUsageDescription; expo-av plugin; android.permission.RECORD_AUDIO (app.config.js:45, 75, 89) | AB18: Expo mobile client | AC18: RP-002 | AD18: User opens VoiceMemoScreen or uses ReviewScreen voice button, records audio via expo-av, navigates to Review with audio URI. | AE18: User reachable | AF18: App.js Stack.Screen name='VoiceMemo' (line 222); VoiceMemoScreen.js; ReviewScreen.js (Audio import); User opens VoiceMemoScreen or uses ReviewScreen voice button, records audio via expo-av, navigates to Review with audio URI. | AG18: Incomplete | AH18: No | AI18: Physical device microphone not verified. Production build not verified. | AJ18: Source traced | AK18: EV-01-0014;EV-01-0035;EV-01-0036;EV-01-0039 | AO18: 8bc0dcb2a1da1b21368c5536aaeef829d587f316 | AP18: Medium | AQ18: Not assessed | AR18: Not assessed | AS18: Fail | AT18: Not assessed | AU18: Not assessed | AV18: Not assessed | AW18: Not assessed | AX18: Not assessed | AY18: Not assessed | AZ18: Not assessed | BA18: Not assessed | BB18: Not assessed | BC18: Not assessed | BD18: Not assessed | BE18: Development required | BF18: Physical implementation is not complete against the stated requirement.; Physical device microphone not verified. Production build not verified. | BG18: Test audio recording on physical device; verify production build. | BK18: Evidence reconciled against the reviewed source revision. No production approval is inferred from implementation or file presence. | BL18: 2026-08-02
A19: BLYP-01-018 | C19: BLYP Bar and AI-assisted posting | D19: 1 | E19: 18 | F19: Feature | G19: Manual post description and caption entry | H19: Manual post description and caption entry | I19: /home/ubuntu/blyp_product_requirements.md :: Section 1 — BLYP Bar and AI-assisted posting | J19: /home/ubuntu/BLYP_COMPLETE_FEATURE_LIST.md:33 | K19: Required | L19: Applicable BLYP member | M19: BLYP mobile application and supporting production services | N19: Manual post description and caption entry | O19: Not explicitly defined in the product source; requires accountable product approval before production sign-off. | P19: Firestore posts collection (caption field, line 1966) | Q19: Yes | S19: End-to-end present | T19: App.js Stack.Screen name='Review' (line 214); ReviewScreen.js | U19: ReviewScreen.js; aiCaptionInput TextInput (line 2582); manualDescription TextInput | V19: caption state; manualDescription state; setCaption; setManualDescription | W19: Not found (caption stored in Firestore post document) | X19: Firestore posts collection (caption field, line 1966) | Y19: Not found | Z19: Not found | AA19: Not found | AB19: Expo mobile client | AC19: RP-002 | AD19: User types description/caption in ReviewScreen TextInput; caption is stored in Firestore post document on submission. | AE19: User reachable | AF19: App.js Stack.Screen name='Review' (line 214); ReviewScreen.js; User types description/caption in ReviewScreen TextInput; caption is stored in Firestore post document on submission. | AG19: Complete against stated requirement | AH19: Yes | AI19: Production build and Firestore write not verified on device. | AJ19: Source traced | AK19: EV-01-0015;EV-01-0033 | AO19: 8bc0dcb2a1da1b21368c5536aaeef829d587f316 | AP19: Medium | AQ19: Not assessed | AR19: Not assessed | AS19: Not assessed | AT19: Not assessed | AU19: Not assessed | AV19: Not assessed | AW19: Not assessed | AX19: Not assessed | AY19: Not assessed | AZ19: Not assessed | BA19: Not assessed | BB19: Not assessed | BC19: Not assessed | BD19: Not assessed | BE19: Ready for production validation | BF19: Applicable production gates and acceptance checks have not been completed on an approved release candidate. | BG19: Test manual caption entry and post creation on device; verify Firestore write. | BK19: Evidence reconciled against the reviewed source revision. No production approval is inferred from implementation or file presence. | BL19: 2026-08-02
A20: BLYP-01-019 | C20: BLYP Bar and AI-assisted posting | D20: 1 | E20: 19 | F20: Feature | G20: Push-to-talk description | H20: Push-to-talk description | I20: /home/ubuntu/blyp_product_requirements.md :: Section 1 — BLYP Bar and AI-assisted posting | J20: /home/ubuntu/BLYP_COMPLETE_FEATURE_LIST.md:34 | K20: Required | L20: Applicable BLYP member | M20: BLYP mobile application and supporting production services | N20: Push-to-talk description | O20: Not explicitly defined in the product source; requires accountable product approval before production sign-off. | P20: Gemini API (for transcription after recording); Local file system (audio URI); NSMicrophoneUsageDescription; expo-av plugin; android.permission.RECORD_AUDIO | Q20: Yes | S20: Partial | T20: ReviewScreen.js; handleVoiceButtonPressIn/PressOut (lines 1001-1015); handleVoiceDescriptionPressIn/PressOut (lines 1494-1513) | U20: ReviewScreen.js; voiceButton (line 2389-2396); description overlay voice button (line 3111-3118) | V20: speechToTextService.startRecording/stopRecording; isRecording state; isTranscribing state | W20: Not found | X20: Local file system (audio URI) | Y20: Not found | Z20: Gemini API (for transcription after recording) | AA20: NSMicrophoneUsageDescription; expo-av plugin; android.permission.RECORD_AUDIO | AB20: Expo mobile client | AC20: RP-002 | AD20: User holds voice button in ReviewScreen (onPressIn/onPressOut), audio is recorded via speechToTextService, transcribed via Gemini, and used as caption input. | AE20: User reachable | AF20: ReviewScreen.js; handleVoiceButtonPressIn/PressOut (lines 1001-1015); handleVoiceDescriptionPressIn/PressOut (lines 1494-1513); User holds voice button in ReviewScreen (onPressIn/onPressOut), audio is recorded via speechToTextService, transcribed via Gemini, and used as caption input. | AG20: Incomplete | AH20: No | AI20: Physical device microphone not verified. Transcription depends on Gemini API key availability. Production build not verified. | AJ20: Source traced | AK20: EV-01-0016;EV-01-0036 | AO20: 8bc0dcb2a1da1b21368c5536aaeef829d587f316 | AP20: Medium | AQ20: Not assessed | AR20: Not assessed | AS20: Fail | AT20: Not assessed | AU20: Not assessed | AV20: Not assessed | AW20: Not assessed | AX20: Not assessed | AY20: Not assessed | AZ20: Not assessed | BA20: Not assessed | BB20: Not assessed | BC20: Not assessed | BD20: Not assessed | BE20: Development required | BF20: Physical implementation is not complete against the stated requirement.; Physical device microphone not verified. Transcription depends on Gemini API key availability. Production build not verified. | BG20: Test push-to-talk on physical device; verify Gemini transcription with production API key. | BK20: Evidence reconciled against the reviewed source revision. No production approval is inferred from implementation or file presence. | BL20: 2026-08-02
A21: BLYP-01-020 | C21: BLYP Bar and AI-assisted posting | D21: 1 | E21: 20 | F21: Feature | G21: Voice-to-text transcription | H21: Voice-to-text transcription | I21: /home/ubuntu/blyp_product_requirements.md :: Section 1 — BLYP Bar and AI-assisted posting | J21: /home/ubuntu/BLYP_COMPLETE_FEATURE_LIST.md:35 | K21: Required | L21: Applicable BLYP member | M21: BLYP mobile application and supporting production services | N21: Voice-to-text transcription | O21: Not explicitly defined in the product source; requires accountable product approval before production sign-off. | P21: Gemini API (generativelanguage.googleapis.com/v1beta/models/gemini-2.5-flash-preview-05-20); Local file system (audio URI); caption/voiceTranscript state; EXPO_PUBLIC_GEMINI_API_KEY; NSMicrophoneUsageDescription | Q21: Yes | S21: Partial | T21: ReviewScreen.js; stopVoiceDescription (line 503-530); VoiceMemoScreen.js | U21: ReviewScreen.js; VoiceMemoScreen.js | V21: geminiSpeechService.transcribeAudio; speechToTextService.transcribeAudio; isTranscribing state; voiceTranscript state | W21: Not found (direct client-to-Gemini API) | X21: Local file system (audio URI); caption/voiceTranscript state | Y21: Not found | Z21: Gemini API (generativelanguage.googleapis.com/v1beta/models/gemini-2.5-flash-preview-05-20) | AA21: EXPO_PUBLIC_GEMINI_API_KEY; NSMicrophoneUsageDescription | AB21: Expo mobile client | AC21: RP-002 | AD21: After recording, ReviewScreen calls geminiSpeechService.transcribeAudio(audioUri) which sends audio to Gemini API for transcription. Transcript is set as caption. | AE21: User reachable | AF21: ReviewScreen.js; stopVoiceDescription (line 503-530); VoiceMemoScreen.js; After recording, ReviewScreen calls geminiSpeechService.transcribeAudio(audioUri) which sends audio to Gemini API for transcription. Transcript is set as caption. | AG21: Incomplete | AH21: No | AI21: speechToTextService.transcribeAudio in demo mode returns placeholder string (line 339). Gemini API key must be present in production build. Physical device not verified. Direct client-to-API call (not server-proxied). | AJ21: Source traced | AK21: EV-01-0017;EV-01-0036 | AO21: 8bc0dcb2a1da1b21368c5536aaeef829d587f316 | AP21: Medium | AQ21: Not assessed | AR21: Not assessed | AS21: Fail | AT21: Not assessed | AU21: Not assessed | AV21: Not assessed | AW21: Not assessed | AX21: Not assessed | AY21: Not assessed | AZ21: Not assessed | BA21: Not assessed | BB21: Not assessed | BC21: Not assessed | BD21: Not assessed | BE21: Development required | BF21: Physical implementation is not complete against the stated requirement.; speechToTextService.transcribeAudio in demo mode returns placeholder string (line 339). Gemini API key must be present in production build. Physical device not verified. Direct client-to-API call (not server-proxied). | BG21: Verify Gemini API key in production build; test transcription on physical device. | BK21: Evidence reconciled against the reviewed source revision. No production approval is inferred from implementation or file presence. | BL21: 2026-08-02
A22: BLYP-01-021 | C22: BLYP Bar and AI-assisted posting | D22: 1 | E22: 21 | F22: Feature | G22: Creative-direction input for AI captions | H22: Creative-direction input for AI captions | I22: /home/ubuntu/blyp_product_requirements.md :: Section 1 — BLYP Bar and AI-assisted posting | J22: /home/ubuntu/BLYP_COMPLETE_FEATURE_LIST.md:36 | K22: Required | L22: Applicable BLYP member | M22: BLYP mobile application and supporting production services | N22: Creative-direction input for AI captions | O22: Not explicitly defined in the product source; requires accountable product approval before production sign-off. | P22: Gemini API (receives creative direction as part of context prompt); EXPO_PUBLIC_GEMINI_API_KEY | Q22: Partial | S22: Partial | T22: ReviewScreen.js; manualDescription TextInput; descriptionText state | U22: ReviewScreen.js; description method overlay; manualDescription input | V22: manualDescription state; descriptionText state; allContextualData.manualText | W22: Not found | X22: Not found | Y22: Not found | Z22: Gemini API (receives creative direction as part of context prompt) | AA22: EXPO_PUBLIC_GEMINI_API_KEY | AB22: Expo mobile client | AC22: RP-002 | AD22: User types creative direction in manualDescription TextInput; text is included in AI context prompt as 'Extra user context' in generateComprehensiveAIContent. | AE22: User reachable | AF22: ReviewScreen.js; manualDescription TextInput; descriptionText state; User types creative direction in manualDescription TextInput; text is included in AI context prompt as 'Extra user context' in generateComprehensiveAIContent. | AG22: Incomplete | AH22: No | AI22: No dedicated 'creative direction' UI label found. The feature is implemented as a general text input that feeds into AI context. No distinct UX flow for creative direction vs. plain caption entry. Production build not verified. | AJ22: Source traced | AK22: EV-01-0018 | AO22: 8bc0dcb2a1da1b21368c5536aaeef829d587f316 | AP22: Low | AQ22: Not assessed | AR22: Not assessed | AS22: Fail | AT22: Not assessed | AU22: Not assessed | AV22: Not assessed | AW22: Not assessed | AX22: Not assessed | AY22: Not assessed | AZ22: Not assessed | BA22: Not assessed | BB22: Not assessed | BC22: Not assessed | BD22: Not assessed | BE22: Development required | BF22: Physical implementation is not complete against the stated requirement.; No dedicated 'creative direction' UI label found. The feature is implemented as a general text input that feeds into AI context. No distinct UX flow for creative direction vs. plain caption entry. Production build not verified. | BG22: Confirm dedicated creative-direction UI; test on device with Gemini API key. | BK22: Evidence reconciled against the reviewed source revision. No production approval is inferred from implementation or file presence. | BL22: 2026-08-02
